<?xml version="1.0"?>
<robot xmlns:xacro="http://www.ros.org/wiki/xacro">
  <xacro:macro name="wheel_macro" params="prefix parent xyz">
    <link name="${prefix}_wheel_link">
      <visual>
        <geometry><cylinder radius="0.05" length="0.02"/></geometry>
        <origin rpy="1.5708 0 0" xyz="0 0 0"/>
        <material name="black"/>
      </visual>
      <collision>
        <geometry><cylinder radius="0.05" length="0.02"/></geometry>
        <origin rpy="1.5708 0 0" xyz="0 0 0"/>
      </collision>
      <inertial>
        <mass value="1.0"/>
        <inertia ixx="0.01" iyy="0.01" izz="0.01"
                 ixy="0.0" ixz="0.0" iyz="0.0"/>
      </inertial>
    </link>
    <joint name="${prefix}_wheel_joint" type="continuous">
      <parent link="${parent}"/>
      <child link="${prefix}_wheel_link"/>
      <origin xyz="${xyz}"/>
      <axis xyz="0 1 0"/>
    </joint>
  </xacro:macro>
</robot>
