<?xml version="1.0"?>
<robot xmlns:xacro="http://ros.org/wiki/xacro">

  <!-- Wheel macro -->
  <xacro:macro name="wheel_macro" params="prefix parent xyz friction">
    <link name="${prefix}_wheel_link">
      <visual>
        <geometry>
          <cylinder radius="0.10" length="0.04"/>
        </geometry>
        <origin rpy="1.5708 0 0" xyz="0 0 0"/>
        <material name="black">
          <color rgba="0 0 0 1"/>
        </material>
      </visual>

      <collision>
        <geometry>
          <cylinder radius="0.10" length="0.04"/>
        </geometry>
        <origin rpy="1.5708 0 0" xyz="0 0 0"/>
      </collision>

      <inertial>
        <mass value="0.5"/>
        <origin xyz="0 0 0"/>
        <inertia ixx="0.001" iyy="0.001" izz="0.001"
                 ixy="0.0" ixz="0.0" iyz="0.0"/>
      </inertial>
    </link>

    <joint name="${prefix}_wheel_joint" type="continuous">
      <parent link="${parent}"/>
      <child link="${prefix}_wheel_link"/>
      <origin xyz="${xyz}" rpy="0 0 0"/>
      <axis xyz="0 1 0"/>
    </joint>

    <!-- Gazebo wheel properties -->
    <gazebo reference="${prefix}_wheel_link">
      <mu1>${friction}</mu1>
      <mu2>${friction}</mu2>
      <material>Gazebo/Black</material>
    </gazebo>

  </xacro:macro>

</robot>
